Workbook

Sheet nodes
A1: node_code | B1: ID | C1: voltage | D1: province | E1: node_type | F1: longitude | G1: latitude | H1: elevation | I1: demand_factor | J1: cf_pv | K1: cf_wind
A2: BC_AAL_DSS | B2: 1 | C2: 230 | D2: BC | E2: Distribution | F2: -116.53811 | G2: 49.140156 | H2: 587 | I2: 0.003363 | J2: 0.155703 | K2: 0.06304
A3: BC_ACK_DSS | B3: 2 | C3: 230 | D3: BC | E3: Distribution | F3: -118.99346 | G3: 50.561355 | H3: 514 | I3: 0.003918 | J3: 0.145822 | K3: 0.040198
A4: BC_ALH_GSS | B4: 3 | C4: 230 | D4: BC | E4: Generation | F4: -117.76885 | G4: 49.343024 | H4: 472 | I4: 0.003363 | J4: 0.149954 | K4: 0.035598
A5: BC_ALZ_DSS | B5: 4 | C5: 230 | D5: BC | E5: Distribution | F5: -122.00932 | G5: 49.113555 | H5: 44 | I5: 0.006494 | J5: 0.131906 | K5: 0.071111
A6: BC_ARN_DSS | B6: 5 | C6: 230 | D6: BC | E6: Distribution | F6: -123.04168 | G6: 49.092139 | H6: 3 | I6: 0.015035 | J6: 0.131679 | K6: 0.088419
A7: BC_ASL_GSS | B7: 6 | C7: 230 | D7: BC | E7: Generation | F7: -123.32482 | G7: 49.913835 | H7: 164 | I7: 0.003087 | J7: 0.136098 | K7: 0.033405
A8: BC_ASL_JCT | B8: 7 | C8: 230 | D8: BC | E8: Junction | F8: -123.29228 | G8: 49.915643 | H8: 65 | I8: 0.003087 | J8: 0.135662 | K8: 0.033941
A9: BC_BCR_ISS | B9: 8 | C9: 230 | D9: BC | E9: Industrial | F9: -121.13262 | G9: 55.147518 | H9: 1011 | I9: 0.003341 | J9: 0.126924 | K9: 0.265221
A10: BC_BDH_GSS | B10: 9 | C10: 230 | D10: BC | E10: Generation | F10: -123.40593 | G10: 50.635524 | H10: 564 | I10: 0.003087 | J10: 0.150874 | K10: 0.038106
A11: BC_BDH_JCT | B11: 10 | C11: 230 | D11: BC | E11: Junction | F11: -123.40892 | G11: 50.635395 | H11: 475 | I11: 0.003087 | J11: 0.150851 | K11: 0.038056
A12: BC_BEN_TSS | B12: 11 | C12: 230 | D12: BC | E12: Terminal | F12: -119.53011 | G12: 49.189206 | H12: 331 | I12: 0.003893 | J12: 0.152324 | K12: 0.071497
A13: BC_BLM_DSS | B13: 12 | C13: 230 | D13: BC | E13: Distribution | F13: -121.46842 | G13: 55.139244 | H13: 1127 | I13: 0.003341 | J13: 0.12419 | K13: 0.242821
... A167: BC_WTS_TSS | B167: 166 | C167: 230 | D167: BC | E167: Terminal | F167: -117.73973 | G167: 49.105169 | H167: 580 | I167: 0.002609 | J167: 0.15074 | K167: 0.046364

Sheet exist
A1: ID | B1: Node | C1: province | D1: latitude | E1: longitude | F1: network_node_code | G1: gen_type | H1: unit_installed_capacity | I1: fixed_om_costs | J1: variable_om_costs | K1: emissions | L1: heat_rate | M1: Max_cap | N1: Prod_cost_t1 | O1: Prod_cost_t2 | P1: Prod_cost_t3 | Q1: Prod_cost_t4 | R1: Prod_cost_t5 | S1: Prod_cost_t6
A2: 1 | B2: =VLOOKUP(F2,nodes!$A$1:$L$167,2) -> 26 | C2: BC | D2: 49.493319 | E2: -115.36242 | F2: BC_CBK_DSS | G2: hydro_daily | H2: 8 | I2: =VLOOKUP(G2,gen_cost!$A$1:$AY$31,15) -> 115196 | J2: =VLOOKUP(G2,gen_cost!$A$1:$AY$31,16) -> 5 | K2: =VLOOKUP(G2,gen_cost!$A$1:$AY$31,21) -> 0 | L2: =VLOOKUP(G2,gen_cost!$A$1:$AY$31,22) -> 0 | M2: =H2/100 -> 0.08 | N2: =J2 -> 5 | O2: =+N2 -> 5 | P2: =+O2 -> 5 | Q2: =+P2 -> 5 | R2: =+Q2 -> 5 | S2: =+R2 -> 5
A3: 2 | B3: =VLOOKUP(F3,nodes!$A$1:$L$167,2) -> 26 | C3: BC | D3: 49.493319 | E3: -115.36242 | F3: BC_CBK_DSS | G3: hydro_daily | H3: 8 | I3: =VLOOKUP(G3,gen_cost!$A$1:$AY$31,15) -> 115196 | J3: =VLOOKUP(G3,gen_cost!$A$1:$AY$31,16) -> 5 | K3: =VLOOKUP(G3,gen_cost!$A$1:$AY$31,21) -> 0 | L3: =VLOOKUP(G3,gen_cost!$A$1:$AY$31,22) -> 0 | M3: =H3/100 -> 0.08 | N3: =J3 -> 5 | O3: =+N3 -> 5 | P3: =+O3 -> 5 | Q3: =+P3 -> 5 | R3: =+Q3 -> 5 | S3: =+R3 -> 5
A4: 3 | B4: =VLOOKUP(F4,nodes!$A$1:$L$167,2) -> 26 | C4: BC | D4: 49.493319 | E4: -115.36242 | F4: BC_CBK_DSS | G4: hydro_daily | H4: 8 | I4: =VLOOKUP(G4,gen_cost!$A$1:$AY$31,15) -> 115196 | J4: =VLOOKUP(G4,gen_cost!$A$1:$AY$31,16) -> 5 | K4: =VLOOKUP(G4,gen_cost!$A$1:$AY$31,21) -> 0 | L4: =VLOOKUP(G4,gen_cost!$A$1:$AY$31,22) -> 0 | M4: =H4/100 -> 0.08 | N4: =J4 -> 5 | O4: =+N4 -> 5 | P4: =+O4 -> 5 | Q4: =+P4 -> 5 | R4: =+Q4 -> 5 | S4: =+R4 -> 5
A5: 4 | B5: =VLOOKUP(F5,nodes!$A$1:$L$167,2) -> 3 | C5: BC | D5: 49.343024 | E5: -117.76885 | F5: BC_ALH_GSS | G5: hydro_daily | H5: 92.5 | I5: =VLOOKUP(G5,gen_cost!$A$1:$AY$31,15) -> 115196 | J5: =VLOOKUP(G5,gen_cost!$A$1:$AY$31,16) -> 5 | K5: =VLOOKUP(G5,gen_cost!$A$1:$AY$31,21) -> 0 | L5: =VLOOKUP(G5,gen_cost!$A$1:$AY$31,22) -> 0 | M5: =H5/100 -> 0.925 | N5: =J5 -> 5 | O5: =+N5 -> 5 | P5: =+O5 -> 5 | Q5: =+P5 -> 5 | R5: =+Q5 -> 5 | S5: =+R5 -> 5
A6: 5 | B6: =VLOOKUP(F6,nodes!$A$1:$L$167,2) -> 3 | C6: BC | D6: 49.343024 | E6: -117.76885 | F6: BC_ALH_GSS | G6: hydro_daily | H6: 92.5 | I6: =VLOOKUP(G6,gen_cost!$A$1:$AY$31,15) -> 115196 | J6: =VLOOKUP(G6,gen_cost!$A$1:$AY$31,16) -> 5 | K6: =VLOOKUP(G6,gen_cost!$A$1:$AY$31,21) -> 0 | L6: =VLOOKUP(G6,gen_cost!$A$1:$AY$31,22) -> 0 | M6: =H6/100 -> 0.925 | N6: =J6 -> 5 | O6: =+N6 -> 5 | P6: =+O6 -> 5 | Q6: =+P6 -> 5 | R6: =+Q6 -> 5 | S6: =+R6 -> 5
A7: 6 | B7: =VLOOKUP(F7,nodes!$A$1:$L$167,2) -> 58 | C7: BC | D7: 50.8227 | E7: -118.0295 | F7: BC_ILL_DSS | G7: hydro_run | H7: 10 | I7: =VLOOKUP(G7,gen_cost!$A$1:$AY$31,15) -> 66563 | J7: =VLOOKUP(G7,gen_cost!$A$1:$AY$31,16) -> 1 | K7: =VLOOKUP(G7,gen_cost!$A$1:$AY$31,21) -> 0 | L7: =VLOOKUP(G7,gen_cost!$A$1:$AY$31,22) -> 0 | M7: =H7/100 -> 0.1 | N7: =J7 -> 1 | O7: =+N7 -> 1 | P7: =+O7 -> 1 | Q7: =+P7 -> 1 | R7: =+Q7 -> 1 | S7: =+R7 -> 1
A8: 7 | B8: =VLOOKUP(F8,nodes!$A$1:$L$167,2) -> 27 | C8: BC | D8: 49.371009 | E8: -122.31243 | F8: BC_CBN_DSS | G8: hydro_daily | H8: 9 | I8: =VLOOKUP(G8,gen_cost!$A$1:$AY$31,15) -> 115196 | J8: =VLOOKUP(G8,gen_cost!$A$1:$AY$31,16) -> 5 | K8: =VLOOKUP(G8,gen_cost!$A$1:$AY$31,21) -> 0 | L8: =VLOOKUP(G8,gen_cost!$A$1:$AY$31,22) -> 0 | M8: =H8/100 -> 0.09 | N8: =J8 -> 5 | O8: =+N8 -> 5 | P8: =+O8 -> 5 | Q8: =+P8 -> 5 | R8: =+Q8 -> 5 | S8: =+R8 -> 5
A9: 8 | B9: =VLOOKUP(F9,nodes!$A$1:$L$167,2) -> 38 | C9: BC | D9: 49.373363 | E9: -125.15063 | F9: BC_DMR_DSS | G9: hydro_daily | H9: 28 | I9: =VLOOKUP(G9,gen_cost!$A$1:$AY$31,15) -> 115196 | J9: =VLOOKUP(G9,gen_cost!$A$1:$AY$31,16) -> 5 | K9: =VLOOKUP(G9,gen_cost!$A$1:$AY$31,21) -> 0 | L9: =VLOOKUP(G9,gen_cost!$A$1:$AY$31,22) -> 0 | M9: =H9/100 -> 0.28 | N9: =J9 -> 5 | O9: =+N9 -> 5 | P9: =+O9 -> 5 | Q9: =+P9 -> 5 | R9: =+Q9 -> 5 | S9: =+R9 -> 5
A10: 9 | B10: =VLOOKUP(F10,nodes!$A$1:$L$167,2) -> 6 | C10: BC | D10: 49.914338 | E10: -123.32503 | F10: BC_ASL_GSS | G10: hydro_run | H10: 49.9 | I10: =VLOOKUP(G10,gen_cost!$A$1:$AY$31,15) -> 66563 | J10: =VLOOKUP(G10,gen_cost!$A$1:$AY$31,16) -> 1 | K10: =VLOOKUP(G10,gen_cost!$A$1:$AY$31,21) -> 0 | L10: =VLOOKUP(G10,gen_cost!$A$1:$AY$31,22) -> 0 | M10: =H10/100 -> 0.499 | N10: =J10 -> 1 | O10: =+N10 -> 1 | P10: =+O10 -> 1 | Q10: =+P10 -> 1 | R10: =+Q10 -> 1 | S10: =+R10 -> 1
A11: 10 | B11: =VLOOKUP(F11,nodes!$A$1:$L$167,2) -> 62 | C11: BC | D11: 49.811453 | E11: -121.45849 | F11: BC_KCH_GSS | G11: hydro_run | H11: 9 | I11: =VLOOKUP(G11,gen_cost!$A$1:$AY$31,15) -> 66563 | J11: =VLOOKUP(G11,gen_cost!$A$1:$AY$31,16) -> 1 | K11: =VLOOKUP(G11,gen_cost!$A$1:$AY$31,21) -> 0 | L11: =VLOOKUP(G11,gen_cost!$A$1:$AY$31,22) -> 0 | M11: =H11/100 -> 0.09 | N11: =J11 -> 1 | O11: =+N11 -> 1 | P11: =+O11 -> 1 | Q11: =+P11 -> 1 | R11: =+Q11 -> 1 | S11: =+R11 -> 1
A12: 11 | B12: =VLOOKUP(F12,nodes!$A$1:$L$167,2) -> 9 | C12: BC | D12: 50.635524 | E12: -123.40593 | F12: BC_BDH_GSS | G12: hydro_run | H12: 25.3 | I12: =VLOOKUP(G12,gen_cost!$A$1:$AY$31,15) -> 66563 | J12: =VLOOKUP(G12,gen_cost!$A$1:$AY$31,16) -> 1 | K12: =VLOOKUP(G12,gen_cost!$A$1:$AY$31,21) -> 0 | L12: =VLOOKUP(G12,gen_cost!$A$1:$AY$31,22) -> 0 | M12: =H12/100 -> 0.253 | N12: =J12 -> 1 | O12: =+N12 -> 1 | P12: =+O12 -> 1 | Q12: =+P12 -> 1 | R12: =+Q12 -> 1 | S12: =+R12 -> 1
A13: 12 | B13: =VLOOKUP(F13,nodes!$A$1:$L$167,2) -> 43 | C13: BC | D13: 50.057918 | E13: -123.13129 | F13: BC_FCN_DSS | G13: hydro_run | H13: 7.6 | I13: =VLOOKUP(G13,gen_cost!$A$1:$AY$31,15) -> 66563 | J13: =VLOOKUP(G13,gen_cost!$A$1:$AY$31,16) -> 1 | K13: =VLOOKUP(G13,gen_cost!$A$1:$AY$31,21) -> 0 | L13: =VLOOKUP(G13,gen_cost!$A$1:$AY$31,22) -> 0 | M13: =H13/100 -> 0.076 | N13: =J13 -> 1 | O13: =+N13 -> 1 | P13: =+O13 -> 1 | Q13: =+P13 -> 1 | R13: =+Q13 -> 1 | S13: =+R13 -> 1
... A267: 266 | B267: =VLOOKUP(F267,nodes!$A$1:$L$167,2) -> 46 | C267: BC | D267: 50.053504 | E267: -126.7798 | F267: BC_GLD_DSS | G267: hydro_daily | H267: 7.3 | I267: =VLOOKUP(G267,gen_cost!$A$1:$AY$31,15) -> 115196 | J267: =VLOOKUP(G267,gen_cost!$A$1:$AY$31,16) -> 5 | K267: =VLOOKUP(G267,gen_cost!$A$1:$AY$31,21) -> 0 | L267: =VLOOKUP(G267,gen_cost!$A$1:$AY$31,22) -> 0 | M267: =H267/100 -> 0.073 | N267: =J267 -> 5 | O267: =+N267 -> 5 | P267: =+O267 -> 5 | Q267: =+P267 -> 5 | R267: =+Q267 -> 5 | S267: =+R267 -> 5

Sheet cand
A1: node_code | B1: ID_ref | C1: voltage | D1: province | E1: cf_pv | F1: cf_wind | G1: ID | H1: Node | I1: gen_type | J1: emissions | K1: heat_rate | L1: Prod_cost_t1 | M1: Prod_cost_t2 | N1: Prod_cost_t3 | O1: Prod_cost_t4 | P1: Prod_cost_t5 | Q1: Prod_cost_t6 | R1: Inv_cost_t1 | S1: Inv_cost_t2 | T1: Inv_cost_t3 | U1: Inv_cost_t4 | V1: Inv_cost_t5 | W1: Inv_cost_t6 | X1: Prod_cap | Y1: Q
A2: BC_QTY_GSS | B2: 111 | C2: 230 | D2: BC | E2: 0.12835 | F2: 0.276245 | G2: 32 | H2: =B2 -> 111 | I2: wind_onshore | J2: =VLOOKUP(I2,gen_cost!$A$1:$AY$31,21) -> 0 | K2: =VLOOKUP(I2,gen_cost!$A$1:$AY$31,22) -> 0 | L2: =VLOOKUP(I2,gen_cost!$A$1:$AY$31,16) -> 0 | M2: =+L2 -> 0 | N2: =+M2 -> 0 | O2: =+N2 -> 0 | P2: =+O2 -> 0 | Q2: =+P2 -> 0 | R2: =VLOOKUP(I2,gen_cost!$A$1:$AY$31,14) -> 298.39 | S2: =+R2 -> 298.39 | T2: =+S2 -> 298.39 | U2: =+T2 -> 298.39 | V2: =+U2 -> 298.39 | W2: =+V2 -> 298.39 | X2: 20 | Y2: 10
A3: BC_MRC_ISS | B3: 93 | C3: 230 | D3: BC | E3: 0.128306 | F3: 0.270971 | G3: 33 | H3: =B3 -> 93 | I3: wind_onshore | J3: =VLOOKUP(I3,gen_cost!$A$1:$AY$31,21) -> 0 | K3: =VLOOKUP(I3,gen_cost!$A$1:$AY$31,22) -> 0 | L3: =VLOOKUP(I3,gen_cost!$A$1:$AY$31,16) -> 0 | M3: =+L3 -> 0 | N3: =+M3 -> 0 | O3: =+N3 -> 0 | P3: =+O3 -> 0 | Q3: =+P3 -> 0 | R3: =VLOOKUP(I3,gen_cost!$A$1:$AY$31,14) -> 298.39 | S3: =+R3 -> 298.39 | T3: =+S3 -> 298.39 | U3: =+T3 -> 298.39 | V3: =+U3 -> 298.39 | W3: =+V3 -> 298.39 | X3: 20 | Y3: 10
A4: BC_QNT_DSS | B4: 109 | C4: 230 | D4: BC | E4: 0.128306 | F4: 0.270971 | G4: 55 | H4: =B4 -> 109 | I4: wind_onshore | J4: =VLOOKUP(I4,gen_cost!$A$1:$AY$31,21) -> 0 | K4: =VLOOKUP(I4,gen_cost!$A$1:$AY$31,22) -> 0 | L4: =VLOOKUP(I4,gen_cost!$A$1:$AY$31,16) -> 0 | M4: =+L4 -> 0 | N4: =+M4 -> 0 | O4: =+N4 -> 0 | P4: =+O4 -> 0 | Q4: =+P4 -> 0 | R4: =VLOOKUP(I4,gen_cost!$A$1:$AY$31,14) -> 298.39 | S4: =+R4 -> 298.39 | T4: =+S4 -> 298.39 | U4: =+T4 -> 298.39 | V4: =+U4 -> 298.39 | W4: =+V4 -> 298.39 | X4: 20 | Y4: 10
A5: BC_MRC_JCT | B5: 94 | C5: 230 | D5: BC | E5: 0.12792 | F5: 0.269426 | G5: 63 | H5: =B5 -> 94 | I5: wind_onshore | J5: =VLOOKUP(I5,gen_cost!$A$1:$AY$31,21) -> 0 | K5: =VLOOKUP(I5,gen_cost!$A$1:$AY$31,22) -> 0 | L5: =VLOOKUP(I5,gen_cost!$A$1:$AY$31,16) -> 0 | M5: =+L5 -> 0 | N5: =+M5 -> 0 | O5: =+N5 -> 0 | P5: =+O5 -> 0 | Q5: =+P5 -> 0 | R5: =VLOOKUP(I5,gen_cost!$A$1:$AY$31,14) -> 298.39 | S5: =+R5 -> 298.39 | T5: =+S5 -> 298.39 | U5: =+T5 -> 298.39 | V5: =+U5 -> 298.39 | W5: =+V5 -> 298.39 | X5: 20 | Y5: 10
A6: BC_BCR_ISS | B6: 8 | C6: 230 | D6: BC | E6: 0.126924 | F6: 0.265221 | G6: 65 | H6: =B6 -> 8 | I6: wind_onshore | J6: =VLOOKUP(I6,gen_cost!$A$1:$AY$31,21) -> 0 | K6: =VLOOKUP(I6,gen_cost!$A$1:$AY$31,22) -> 0 | L6: =VLOOKUP(I6,gen_cost!$A$1:$AY$31,16) -> 0 | M6: =+L6 -> 0 | N6: =+M6 -> 0 | O6: =+N6 -> 0 | P6: =+O6 -> 0 | Q6: =+P6 -> 0 | R6: =VLOOKUP(I6,gen_cost!$A$1:$AY$31,14) -> 298.39 | S6: =+R6 -> 298.39 | T6: =+S6 -> 298.39 | U6: =+T6 -> 298.39 | V6: =+U6 -> 298.39 | W6: =+V6 -> 298.39 | X6: 20 | Y6: 10
A7: BC_TLR_DSS | B7: 149 | C7: 230 | D7: BC | E7: 0.126916 | F7: 0.26518 | G7: 66 | H7: =B7 -> 149 | I7: wind_onshore | J7: =VLOOKUP(I7,gen_cost!$A$1:$AY$31,21) -> 0 | K7: =VLOOKUP(I7,gen_cost!$A$1:$AY$31,22) -> 0 | L7: =VLOOKUP(I7,gen_cost!$A$1:$AY$31,16) -> 0 | M7: =+L7 -> 0 | N7: =+M7 -> 0 | O7: =+N7 -> 0 | P7: =+O7 -> 0 | Q7: =+P7 -> 0 | R7: =VLOOKUP(I7,gen_cost!$A$1:$AY$31,14) -> 298.39 | S7: =+R7 -> 298.39 | T7: =+S7 -> 298.39 | U7: =+T7 -> 298.39 | V7: =+U7 -> 298.39 | W7: =+V7 -> 298.39 | X7: 20 | Y7: 10
A8: BC_MLW_GSS | B8: 87 | C8: 230 | D8: BC | E8: 0.126263 | F8: 0.262828 | G8: 67 | H8: =B8 -> 87 | I8: wind_onshore | J8: =VLOOKUP(I8,gen_cost!$A$1:$AY$31,21) -> 0 | K8: =VLOOKUP(I8,gen_cost!$A$1:$AY$31,22) -> 0 | L8: =VLOOKUP(I8,gen_cost!$A$1:$AY$31,16) -> 0 | M8: =+L8 -> 0 | N8: =+M8 -> 0 | O8: =+N8 -> 0 | P8: =+O8 -> 0 | Q8: =+P8 -> 0 | R8: =VLOOKUP(I8,gen_cost!$A$1:$AY$31,14) -> 298.39 | S8: =+R8 -> 298.39 | T8: =+S8 -> 298.39 | U8: =+T8 -> 298.39 | V8: =+U8 -> 298.39 | W8: =+V8 -> 298.39 | X8: 20 | Y8: 10
A9: BC_MLW_JCT | B9: 88 | C9: 230 | D9: BC | E9: 0.125268 | F9: 0.256032 | G9: 68 | H9: =B9 -> 88 | I9: wind_onshore | J9: =VLOOKUP(I9,gen_cost!$A$1:$AY$31,21) -> 0 | K9: =VLOOKUP(I9,gen_cost!$A$1:$AY$31,22) -> 0 | L9: =VLOOKUP(I9,gen_cost!$A$1:$AY$31,16) -> 0 | M9: =+L9 -> 0 | N9: =+M9 -> 0 | O9: =+N9 -> 0 | P9: =+O9 -> 0 | Q9: =+P9 -> 0 | R9: =VLOOKUP(I9,gen_cost!$A$1:$AY$31,14) -> 298.39 | S9: =+R9 -> 298.39 | T9: =+S9 -> 298.39 | U9: =+T9 -> 298.39 | V9: =+U9 -> 298.39 | W9: =+V9 -> 298.39 | X9: 20 | Y9: 10
A10: BC_MNK_JCT | B10: 91 | C10: 230 | D10: BC | E10: 0.123835 | F10: 0.255795 | G10: 32 | H10: 2 | I10: solar_PV | J10: =VLOOKUP(I10,gen_cost!$A$1:$AY$31,21) -> 0 | K10: =VLOOKUP(I10,gen_cost!$A$1:$AY$31,22) -> 0 | L10: =VLOOKUP(I10,gen_cost!$A$1:$AY$31,16) -> 0 | M10: =+L10 -> 0 | N10: =+M10 -> 0 | O10: =+N10 -> 0 | P10: =+O10 -> 0 | Q10: =+P10 -> 0 | R10: =VLOOKUP(I10,gen_cost!$A$1:$AY$31,14) -> 201.62 | S10: =+R10 -> 201.62 | T10: =+S10 -> 201.62 | U10: =+T10 -> 201.62 | V10: =+U10 -> 201.62 | W10: =+V10 -> 201.62 | X10: 20 | Y10: 10
A11: BC_SNK_DSS | B11: 133 | C11: 230 | D11: BC | E11: 0.123834 | F11: 0.255664 | G11: 33 | H11: 3 | I11: solar_PV | J11: =VLOOKUP(I11,gen_cost!$A$1:$AY$31,21) -> 0 | K11: =VLOOKUP(I11,gen_cost!$A$1:$AY$31,22) -> 0 | L11: =VLOOKUP(I11,gen_cost!$A$1:$AY$31,16) -> 0 | M11: =+L11 -> 0 | N11: =+M11 -> 0 | O11: =+N11 -> 0 | P11: =+O11 -> 0 | Q11: =+P11 -> 0 | R11: =VLOOKUP(I11,gen_cost!$A$1:$AY$31,14) -> 201.62 | S11: =+R11 -> 201.62 | T11: =+S11 -> 201.62 | U11: =+T11 -> 201.62 | V11: =+U11 -> 201.62 | W11: =+V11 -> 201.62 | X11: 20 | Y11: 10
A12: BC_KGP_JCT | B12: 65 | C12: 230 | D12: BC | E12: 0.123819 | F12: 0.255626 | G12: 55 | H12: 32 | I12: solar_PV | J12: =VLOOKUP(I12,gen_cost!$A$1:$AY$31,21) -> 0 | K12: =VLOOKUP(I12,gen_cost!$A$1:$AY$31,22) -> 0 | L12: =VLOOKUP(I12,gen_cost!$A$1:$AY$31,16) -> 0 | M12: =+L12 -> 0 | N12: =+M12 -> 0 | O12: =+N12 -> 0 | P12: =+O12 -> 0 | Q12: =+P12 -> 0 | R12: =VLOOKUP(I12,gen_cost!$A$1:$AY$31,14) -> 201.62 | S12: =+R12 -> 201.62 | T12: =+S12 -> 201.62 | U12: =+T12 -> 201.62 | V12: =+U12 -> 201.62 | W12: =+V12 -> 201.62 | X12: 20 | Y12: 10
A13: BC_MKT_SWS | B13: 84 | C13: 230 | D13: BC | E13: 0.125032 | F13: 0.254449 | G13: 63 | H13: 31 | I13: solar_PV | J13: =VLOOKUP(I13,gen_cost!$A$1:$AY$31,21) -> 0 | K13: =VLOOKUP(I13,gen_cost!$A$1:$AY$31,22) -> 0 | L13: =VLOOKUP(I13,gen_cost!$A$1:$AY$31,16) -> 0 | M13: =+L13 -> 0 | N13: =+M13 -> 0 | O13: =+N13 -> 0 | P13: =+O13 -> 0 | Q13: =+P13 -> 0 | R13: =VLOOKUP(I13,gen_cost!$A$1:$AY$31,14) -> 201.62 | S13: =+R13 -> 201.62 | T13: =+S13 -> 201.62 | U13: =+T13 -> 201.62 | V13: =+U13 -> 201.62 | W13: =+V13 -> 201.62 | X13: 20 | Y13: 10
A14: BC_MKL_GSS | B14: 83 | C14: 230 | D14: BC | E14: 0.124549 | F14: 0.251084 | G14: 65 | H14: 1 | I14: solar_PV | J14: =VLOOKUP(I14,gen_cost!$A$1:$AY$31,21) -> 0 | K14: =VLOOKUP(I14,gen_cost!$A$1:$AY$31,22) -> 0 | L14: =VLOOKUP(I14,gen_cost!$A$1:$AY$31,16) -> 0 | M14: =+L14 -> 0 | N14: =+M14 -> 0 | O14: =+N14 -> 0 | P14: =+O14 -> 0 | Q14: =+P14 -> 0 | R14: =VLOOKUP(I14,gen_cost!$A$1:$AY$31,14) -> 201.62 | S14: =+R14 -> 201.62 | T14: =+S14 -> 201.62 | U14: =+T14 -> 201.62 | V14: =+U14 -> 201.62 | W14: =+V14 -> 201.62 | X14: 20 | Y14: 10
A15: BC_SLS_DSS | B15: 132 | C15: 230 | D15: BC | E15: 0.125557 | F15: 0.246919 | G15: 66 | H15: 81 | I15: solar_PV | J15: =VLOOKUP(I15,gen_cost!$A$1:$AY$31,21) -> 0 | K15: =VLOOKUP(I15,gen_cost!$A$1:$AY$31,22) -> 0 | L15: =VLOOKUP(I15,gen_cost!$A$1:$AY$31,16) -> 0 | M15: =+L15 -> 0 | N15: =+M15 -> 0 | O15: =+N15 -> 0 | P15: =+O15 -> 0 | Q15: =+P15 -> 0 | R15: =VLOOKUP(I15,gen_cost!$A$1:$AY$31,14) -> 201.62 | S15: =+R15 -> 201.62 | T15: =+S15 -> 201.62 | U15: =+T15 -> 201.62 | V15: =+U15 -> 201.62 | W15: =+V15 -> 201.62 | X15: 20 | Y15: 10
A16: BC_SGB_ISS | B16: 130 | C16: 230 | D16: BC | E16: 0.125944 | F16: 0.245564 | G16: 67 | H16: 46 | I16: solar_PV | J16: =VLOOKUP(I16,gen_cost!$A$1:$AY$31,21) -> 0 | K16: =VLOOKUP(I16,gen_cost!$A$1:$AY$31,22) -> 0 | L16: =VLOOKUP(I16,gen_cost!$A$1:$AY$31,16) -> 0 | M16: =+L16 -> 0 | N16: =+M16 -> 0 | O16: =+N16 -> 0 | P16: =+O16 -> 0 | Q16: =+P16 -> 0 | R16: =VLOOKUP(I16,gen_cost!$A$1:$AY$31,14) -> 201.62 | S16: =+R16 -> 201.62 | T16: =+S16 -> 201.62 | U16: =+T16 -> 201.62 | V16: =+U16 -> 201.62 | W16: =+V16 -> 201.62 | X16: 20 | Y16: 10
A17: BC_BMT_DSS | B17: 14 | C17: 230 | D17: BC | E17: 0.12563 | F17: 0.242943 | G17: 68 | H17: 45 | I17: solar_PV | J17: =VLOOKUP(I17,gen_cost!$A$1:$AY$31,21) -> 0 | K17: =VLOOKUP(I17,gen_cost!$A$1:$AY$31,22) -> 0 | L17: =VLOOKUP(I17,gen_cost!$A$1:$AY$31,16) -> 0 | M17: =+L17 -> 0 | N17: =+M17 -> 0 | O17: =+N17 -> 0 | P17: =+O17 -> 0 | Q17: =+P17 -> 0 | R17: =VLOOKUP(I17,gen_cost!$A$1:$AY$31,14) -> 201.62 | S17: =+R17 -> 201.62 | T17: =+S17 -> 201.62 | U17: =+T17 -> 201.62 | V17: =+U17 -> 201.62 | W17: =+V17 -> 201.62 | X17: 20 | Y17: 10
A18: BC_BLM_DSS | B18: 12 | C18: 230 | D18: BC | E18: 0.12419 | F18: 0.242821 | G18: 32 | H18: 2 | I18: NG_CCS | J18: =VLOOKUP(I18,gen_cost!$A$1:$AY$31,21) -> 0.037998 | K18: =VLOOKUP(I18,gen_cost!$A$1:$AY$31,22) -> 7.16 | L18: =VLOOKUP(I18,gen_cost!$A$1:$AY$31,16) -> 8.54 | M18: =+L18 -> 8.54 | N18: =+M18 -> 8.54 | O18: =+N18 -> 8.54 | P18: =+O18 -> 8.54 | Q18: =+P18 -> 8.54 | R18: =VLOOKUP(I18,gen_cost!$A$1:$AY$31,14) -> 442.87 | S18: =+R18 -> 442.87 | T18: =+S18 -> 442.87 | U18: =+T18 -> 442.87 | V18: =+U18 -> 442.87 | W18: =+V18 -> 442.87 | X18: 20 | Y18: 10
A19: BC_LAP_GSS | B19: 75 | C19: 230 | D19: BC | E19: 0.124004 | F19: 0.238445 | G19: 33 | H19: 3 | I19: NG_CCS | J19: =VLOOKUP(I19,gen_cost!$A$1:$AY$31,21) -> 0.037998 | K19: =VLOOKUP(I19,gen_cost!$A$1:$AY$31,22) -> 7.16 | L19: =VLOOKUP(I19,gen_cost!$A$1:$AY$31,16) -> 8.54 | M19: =+L19 -> 8.54 | N19: =+M19 -> 8.54 | O19: =+N19 -> 8.54 | P19: =+O19 -> 8.54 | Q19: =+P19 -> 8.54 | R19: =VLOOKUP(I19,gen_cost!$A$1:$AY$31,14) -> 442.87 | S19: =+R19 -> 442.87 | T19: =+S19 -> 442.87 | U19: =+T19 -> 442.87 | V19: =+U19 -> 442.87 | W19: =+V19 -> 442.87 | X19: 20 | Y19: 10
A20: BC_MNK_ISS | B20: 90 | C20: 230 | D20: BC | E20: 0.121778 | F20: 0.235469 | G20: 55 | H20: 32 | I20: NG_CCS | J20: =VLOOKUP(I20,gen_cost!$A$1:$AY$31,21) -> 0.037998 | K20: =VLOOKUP(I20,gen_cost!$A$1:$AY$31,22) -> 7.16 | L20: =VLOOKUP(I20,gen_cost!$A$1:$AY$31,16) -> 8.54 | M20: =+L20 -> 8.54 | N20: =+M20 -> 8.54 | O20: =+N20 -> 8.54 | P20: =+O20 -> 8.54 | Q20: =+P20 -> 8.54 | R20: =VLOOKUP(I20,gen_cost!$A$1:$AY$31,14) -> 442.87 | S20: =+R20 -> 442.87 | T20: =+S20 -> 442.87 | U20: =+T20 -> 442.87 | V20: =+U20 -> 442.87 | W20: =+V20 -> 442.87 | X20: 20 | Y20: 10
A21: BC_RUP_DSS | B21: 119 | C21: 287 | D21: BC | E21: 0.102163 | F21: 0.234133 | G21: 63 | H21: 31 | I21: NG_CCS | J21: =VLOOKUP(I21,gen_cost!$A$1:$AY$31,21) -> 0.037998 | K21: =VLOOKUP(I21,gen_cost!$A$1:$AY$31,22) -> 7.16 | L21: =VLOOKUP(I21,gen_cost!$A$1:$AY$31,16) -> 8.54 | M21: =+L21 -> 8.54 | N21: =+M21 -> 8.54 | O21: =+N21 -> 8.54 | P21: =+O21 -> 8.54 | Q21: =+P21 -> 8.54 | R21: =VLOOKUP(I21,gen_cost!$A$1:$AY$31,14) -> 442.87 | S21: =+R21 -> 442.87 | T21: =+S21 -> 442.87 | U21: =+T21 -> 442.87 | V21: =+U21 -> 442.87 | W21: =+V21 -> 442.87 | X21: 20 | Y21: 10
... A33: BC_WSN_DSS | B33: 165 | C33: 230 | D33: BC | E33: 0.127911 | F33: 0.161535 | G33: 68 | H33: 45 | I33: NG_CCS | J33: =VLOOKUP(I33,gen_cost!$A$1:$AY$31,21) -> 0.037998 | K33: =VLOOKUP(I33,gen_cost!$A$1:$AY$31,22) -> 7.16 | L33: =VLOOKUP(I33,gen_cost!$A$1:$AY$31,16) -> 8.54 | M33: =+L33 -> 8.54 | N33: =+M33 -> 8.54 | O33: =+N33 -> 8.54 | P33: =+O33 -> 8.54 | Q33: =+P33 -> 8.54 | R33: =VLOOKUP(I33,gen_cost!$A$1:$AY$31,14) -> 442.87 | S33: =+R33 -> 442.87 | T33: =+S33 -> 442.87 | U33: =+T33 -> 442.87 | V33: =+U33 -> 442.87 | W33: =+V33 -> 442.87 | X33: 20 | Y33: 10
A34: BC_GLN_DSS | B34: 47 | C34: 230 | D34: BC | E34: 0.126067 | F34: 0.158862 | G34: 53 | H34: =B34 -> 47 | I34: wind_onshore | J34: =VLOOKUP(I34,gen_cost!$A$1:$AY$31,21) -> 0 | K34: =VLOOKUP(I34,gen_cost!$A$1:$AY$31,22) -> 0 | L34: =VLOOKUP(I34,gen_cost!$A$1:$AY$31,16) -> 0 | M34: =+L34 -> 0 | N34: =+M34 -> 0 | O34: =+N34 -> 0 | P34: =+O34 -> 0 | Q34: =+P34 -> 0 | R34: =VLOOKUP(I34,gen_cost!$A$1:$AY$31,14) -> 298.39 | S34: =+R34 -> 298.39 | T34: =+S34 -> 298.39 | U34: =+T34 -> 298.39 | V34: =+U34 -> 298.39 | W34: =+V34 -> 298.39 | X34: 20 | Y34: 10
A35: BC_MML_DSS | B35: 89 | C35: 230 | D35: BC | E35: 0.123671 | F35: 0.15585 | G35: 62 | H35: =B35 -> 89 | I35: wind_onshore | J35: =VLOOKUP(I35,gen_cost!$A$1:$AY$31,21) -> 0 | K35: =VLOOKUP(I35,gen_cost!$A$1:$AY$31,22) -> 0 | L35: =VLOOKUP(I35,gen_cost!$A$1:$AY$31,16) -> 0 | M35: =+L35 -> 0 | N35: =+M35 -> 0 | O35: =+N35 -> 0 | P35: =+O35 -> 0 | Q35: =+P35 -> 0 | R35: =VLOOKUP(I35,gen_cost!$A$1:$AY$31,14) -> 298.39 | S35: =+R35 -> 298.39 | T35: =+S35 -> 298.39 | U35: =+T35 -> 298.39 | V35: =+U35 -> 298.39 | W35: =+V35 -> 298.39 | X35: 20 | Y35: 10
A36: BC_SVY_DSS | B36: 140 | C36: 230 | D36: BC | E36: 0.126986 | F36: 0.15582 | G36: 53 | H36: 398 | I36: solar_PV | J36: =VLOOKUP(I36,gen_cost!$A$1:$AY$31,21) -> 0 | K36: =VLOOKUP(I36,gen_cost!$A$1:$AY$31,22) -> 0 | L36: =VLOOKUP(I36,gen_cost!$A$1:$AY$31,16) -> 0 | M36: =+L36 -> 0 | N36: =+M36 -> 0 | O36: =+N36 -> 0 | P36: =+O36 -> 0 | Q36: =+P36 -> 0 | R36: =VLOOKUP(I36,gen_cost!$A$1:$AY$31,14) -> 201.62 | S36: =+R36 -> 201.62 | T36: =+S36 -> 201.62 | U36: =+T36 -> 201.62 | V36: =+U36 -> 201.62 | W36: =+V36 -> 201.62 | X36: 20 | Y36: 10
A37: BC_GTP_DSS | B37: 50 | C37: 230 | D37: BC | E37: 0.137418 | F37: 0.149376 | G37: 62 | H37: 400 | I37: solar_PV | J37: =VLOOKUP(I37,gen_cost!$A$1:$AY$31,21) -> 0 | K37: =VLOOKUP(I37,gen_cost!$A$1:$AY$31,22) -> 0 | L37: =VLOOKUP(I37,gen_cost!$A$1:$AY$31,16) -> 0 | M37: =+L37 -> 0 | N37: =+M37 -> 0 | O37: =+N37 -> 0 | P37: =+O37 -> 0 | Q37: =+P37 -> 0 | R37: =VLOOKUP(I37,gen_cost!$A$1:$AY$31,14) -> 201.62 | S37: =+R37 -> 201.62 | T37: =+S37 -> 201.62 | U37: =+T37 -> 201.62 | V37: =+U37 -> 201.62 | W37: =+V37 -> 201.62 | X37: 20 | Y37: 10
A38: BC_BLW_DSS | B38: 13 | C38: 230 | D38: BC | E38: 0.133289 | F38: 0.149361 | G38: 53 | H38: 398 | I38: NG_CCS | J38: =VLOOKUP(I38,gen_cost!$A$1:$AY$31,21) -> 0.037998 | K38: =VLOOKUP(I38,gen_cost!$A$1:$AY$31,22) -> 7.16 | L38: =VLOOKUP(I38,gen_cost!$A$1:$AY$31,16) -> 8.54 | M38: =+L38 -> 8.54 | N38: =+M38 -> 8.54 | O38: =+N38 -> 8.54 | P38: =+O38 -> 8.54 | Q38: =+P38 -> 8.54 | R38: =VLOOKUP(I38,gen_cost!$A$1:$AY$31,14) -> 442.87 | S38: =+R38 -> 442.87 | T38: =+S38 -> 442.87 | U38: =+T38 -> 442.87 | V38: =+U38 -> 442.87 | W38: =+V38 -> 442.87 | X38: 20 | Y38: 10
A39: BC_QRP_ISS | B39: 110 | C39: 230 | D39: BC | E39: 0.133668 | F39: 0.148623 | G39: 62 | H39: 400 | I39: NG_CCS | J39: =VLOOKUP(I39,gen_cost!$A$1:$AY$31,21) -> 0.037998 | K39: =VLOOKUP(I39,gen_cost!$A$1:$AY$31,22) -> 7.16 | L39: =VLOOKUP(I39,gen_cost!$A$1:$AY$31,16) -> 8.54 | M39: =+L39 -> 8.54 | N39: =+M39 -> 8.54 | O39: =+N39 -> 8.54 | P39: =+O39 -> 8.54 | Q39: =+P39 -> 8.54 | R39: =VLOOKUP(I39,gen_cost!$A$1:$AY$31,14) -> 442.87 | S39: =+R39 -> 442.87 | T39: =+S39 -> 442.87 | U39: =+T39 -> 442.87 | V39: =+U39 -> 442.87 | W39: =+V39 -> 442.87 | X39: 20 | Y39: 10
A40: BC_RBF_DSS | B40: 112 | C40: 230 | D40: BC | E40: 0.133668 | F40: 0.148623 | G40: 53 | H40: 398 | I40: NG_CCS | J40: =VLOOKUP(I40,gen_cost!$A$1:$AY$31,21) -> 0.037998 | K40: =VLOOKUP(I40,gen_cost!$A$1:$AY$31,22) -> 7.16 | L40: =VLOOKUP(I40,gen_cost!$A$1:$AY$31,16) -> 8.54 | M40: =+L40 -> 8.54 | N40: =+M40 -> 8.54 | O40: =+N40 -> 8.54 | P40: =+O40 -> 8.54 | Q40: =+P40 -> 8.54 | R40: =VLOOKUP(I40,gen_cost!$A$1:$AY$31,14) -> 442.87 | S40: =+R40 -> 442.87 | T40: =+S40 -> 442.87 | U40: =+T40 -> 442.87 | V40: =+U40 -> 442.87 | W40: =+V40 -> 442.87 | X40: 20 | Y40: 10
A41: BC_GOW_DSS | B41: 49 | C41: 230 | D41: BC | E41: 0.137082 | F41: 0.148065 | G41: 62 | H41: 400 | I41: NG_CCS | J41: =VLOOKUP(I41,gen_cost!$A$1:$AY$31,21) -> 0.037998 | K41: =VLOOKUP(I41,gen_cost!$A$1:$AY$31,22) -> 7.16 | L41: =VLOOKUP(I41,gen_cost!$A$1:$AY$31,16) -> 8.54 | M41: =+L41 -> 8.54 | N41: =+M41 -> 8.54 | O41: =+N41 -> 8.54 | P41: =+O41 -> 8.54 | Q41: =+P41 -> 8.54 | R41: =VLOOKUP(I41,gen_cost!$A$1:$AY$31,14) -> 442.87 | S41: =+R41 -> 442.87 | T41: =+S41 -> 442.87 | U41: =+T41 -> 442.87 | V41: =+U41 -> 442.87 | W41: =+V41 -> 442.87 | X41: 20 | Y41: 10
A42: BC_PIK_DSS | B42: 107 | C42: 230 | D42: BC | E42: 0.136991 | F42: 0.146435 | G42: 10 | H42: =B42 -> 107 | I42: wind_onshore | J42: =VLOOKUP(I42,gen_cost!$A$1:$AY$31,21) -> 0 | K42: =VLOOKUP(I42,gen_cost!$A$1:$AY$31,22) -> 0 | L42: =VLOOKUP(I42,gen_cost!$A$1:$AY$31,16) -> 0 | M42: =+L42 -> 0 | N42: =+M42 -> 0 | O42: =+N42 -> 0 | P42: =+O42 -> 0 | Q42: =+P42 -> 0 | R42: =VLOOKUP(I42,gen_cost!$A$1:$AY$31,14) -> 298.39 | S42: =+R42 -> 298.39 | T42: =+S42 -> 298.39 | U42: =+T42 -> 298.39 | V42: =+U42 -> 298.39 | W42: =+V42 -> 298.39 | X42: 20 | Y42: 10
A43: BC_SCK_DSS | B43: 127 | C43: 230 | D43: BC | E43: 0.137213 | F43: 0.146255 | G43: 11 | H43: =B43 -> 127 | I43: wind_onshore | J43: =VLOOKUP(I43,gen_cost!$A$1:$AY$31,21) -> 0 | K43: =VLOOKUP(I43,gen_cost!$A$1:$AY$31,22) -> 0 | L43: =VLOOKUP(I43,gen_cost!$A$1:$AY$31,16) -> 0 | M43: =+L43 -> 0 | N43: =+M43 -> 0 | O43: =+N43 -> 0 | P43: =+O43 -> 0 | Q43: =+P43 -> 0 | R43: =VLOOKUP(I43,gen_cost!$A$1:$AY$31,14) -> 298.39 | S43: =+R43 -> 298.39 | T43: =+S43 -> 298.39 | U43: =+T43 -> 298.39 | V43: =+U43 -> 298.39 | W43: =+V43 -> 298.39 | X43: 20 | Y43: 10
A44: BC_HSY_DSS | B44: 55 | C44: 230 | D44: BC | E44: 0.137729 | F44: 0.146134 | G44: 17 | H44: =B44 -> 55 | I44: wind_onshore | J44: =VLOOKUP(I44,gen_cost!$A$1:$AY$31,21) -> 0 | K44: =VLOOKUP(I44,gen_cost!$A$1:$AY$31,22) -> 0 | L44: =VLOOKUP(I44,gen_cost!$A$1:$AY$31,16) -> 0 | M44: =+L44 -> 0 | N44: =+M44 -> 0 | O44: =+N44 -> 0 | P44: =+O44 -> 0 | Q44: =+P44 -> 0 | R44: =VLOOKUP(I44,gen_cost!$A$1:$AY$31,14) -> 298.39 | S44: =+R44 -> 298.39 | T44: =+S44 -> 298.39 | U44: =+T44 -> 298.39 | V44: =+U44 -> 298.39 | W44: =+V44 -> 298.39 | X44: 20 | Y44: 10
A45: BC_ESQ_DSS | B45: 40 | C45: 230 | D45: BC | E45: 0.137296 | F45: 0.144657 | G45: 54 | H45: =B45 -> 40 | I45: wind_onshore | J45: =VLOOKUP(I45,gen_cost!$A$1:$AY$31,21) -> 0 | K45: =VLOOKUP(I45,gen_cost!$A$1:$AY$31,22) -> 0 | L45: =VLOOKUP(I45,gen_cost!$A$1:$AY$31,16) -> 0 | M45: =+L45 -> 0 | N45: =+M45 -> 0 | O45: =+N45 -> 0 | P45: =+O45 -> 0 | Q45: =+P45 -> 0 | R45: =VLOOKUP(I45,gen_cost!$A$1:$AY$31,14) -> 298.39 | S45: =+R45 -> 298.39 | T45: =+S45 -> 298.39 | U45: =+T45 -> 298.39 | V45: =+U45 -> 298.39 | W45: =+V45 -> 298.39 | X45: 20 | Y45: 10
A46: BC_BNT_DSS | B46: 16 | C46: 230 | D46: BC | E46: 0.137296 | F46: 0.144656 | G46: 56 | H46: =B46 -> 16 | I46: wind_onshore | J46: =VLOOKUP(I46,gen_cost!$A$1:$AY$31,21) -> 0 | K46: =VLOOKUP(I46,gen_cost!$A$1:$AY$31,22) -> 0 | L46: =VLOOKUP(I46,gen_cost!$A$1:$AY$31,16) -> 0 | M46: =+L46 -> 0 | N46: =+M46 -> 0 | O46: =+N46 -> 0 | P46: =+O46 -> 0 | Q46: =+P46 -> 0 | R46: =VLOOKUP(I46,gen_cost!$A$1:$AY$31,14) -> 298.39 | S46: =+R46 -> 298.39 | T46: =+S46 -> 298.39 | U46: =+T46 -> 298.39 | V46: =+U46 -> 298.39 | W46: =+V46 -> 298.39 | X46: 20 | Y46: 10
A47: BC_KTG_DSS | B47: 74 | C47: 230 | D47: BC | E47: 0.136505 | F47: 0.140992 | G47: 10 | H47: 443 | I47: solar_PV | J47: =VLOOKUP(I47,gen_cost!$A$1:$AY$31,21) -> 0 | K47: =VLOOKUP(I47,gen_cost!$A$1:$AY$31,22) -> 0 | L47: =VLOOKUP(I47,gen_cost!$A$1:$AY$31,16) -> 0 | M47: =+L47 -> 0 | N47: =+M47 -> 0 | O47: =+N47 -> 0 | P47: =+O47 -> 0 | Q47: =+P47 -> 0 | R47: =VLOOKUP(I47,gen_cost!$A$1:$AY$31,14) -> 201.62 | S47: =+R47 -> 201.62 | T47: =+S47 -> 201.62 | U47: =+T47 -> 201.62 | V47: =+U47 -> 201.62 | W47: =+V47 -> 201.62 | X47: 20 | Y47: 10
A48: BC_GLD_DSS | B48: 46 | C48: 230 | D48: BC | E48: 0.127067 | F48: 0.139251 | G48: 11 | H48: 439 | I48: solar_PV | J48: =VLOOKUP(I48,gen_cost!$A$1:$AY$31,21) -> 0 | K48: =VLOOKUP(I48,gen_cost!$A$1:$AY$31,22) -> 0 | L48: =VLOOKUP(I48,gen_cost!$A$1:$AY$31,16) -> 0 | M48: =+L48 -> 0 | N48: =+M48 -> 0 | O48: =+N48 -> 0 | P48: =+O48 -> 0 | Q48: =+P48 -> 0 | R48: =VLOOKUP(I48,gen_cost!$A$1:$AY$31,14) -> 201.62 | S48: =+R48 -> 201.62 | T48: =+S48 -> 201.62 | U48: =+T48 -> 201.62 | V48: =+U48 -> 201.62 | W48: =+V48 -> 201.62 | X48: 20 | Y48: 10
A49: BC_NTL_DSS | B49: 103 | C49: 138 | D49: BC | E49: 0.161794 | F49: 0.134662 | G49: 17 | H49: 445 | I49: solar_PV | J49: =VLOOKUP(I49,gen_cost!$A$1:$AY$31,21) -> 0 | K49: =VLOOKUP(I49,gen_cost!$A$1:$AY$31,22) -> 0 | L49: =VLOOKUP(I49,gen_cost!$A$1:$AY$31,16) -> 0 | M49: =+L49 -> 0 | N49: =+M49 -> 0 | O49: =+N49 -> 0 | P49: =+O49 -> 0 | Q49: =+P49 -> 0 | R49: =VLOOKUP(I49,gen_cost!$A$1:$AY$31,14) -> 201.62 | S49: =+R49 -> 201.62 | T49: =+S49 -> 201.62 | U49: =+T49 -> 201.62 | V49: =+U49 -> 201.62 | W49: =+V49 -> 201.62 | X49: 20 | Y49: 10
A50: BC_NIC_TSS | B50: 101 | C50: 230 | D50: BC | E50: 0.143589 | F50: 0.132285 | G50: 54 | H50: 453 | I50: solar_PV | J50: =VLOOKUP(I50,gen_cost!$A$1:$AY$31,21) -> 0 | K50: =VLOOKUP(I50,gen_cost!$A$1:$AY$31,22) -> 0 | L50: =VLOOKUP(I50,gen_cost!$A$1:$AY$31,16) -> 0 | M50: =+L50 -> 0 | N50: =+M50 -> 0 | O50: =+N50 -> 0 | P50: =+O50 -> 0 | Q50: =+P50 -> 0 | R50: =VLOOKUP(I50,gen_cost!$A$1:$AY$31,14) -> 201.62 | S50: =+R50 -> 201.62 | T50: =+S50 -> 201.62 | U50: =+T50 -> 201.62 | V50: =+U50 -> 201.62 | W50: =+V50 -> 201.62 | X50: 20 | Y50: 10
A51: BC_TKW_DSS | B51: 148 | C51: 500 | D51: BC | E51: 0.128744 | F51: 0.122983 | G51: 56 | H51: 438 | I51: solar_PV | J51: =VLOOKUP(I51,gen_cost!$A$1:$AY$31,21) -> 0 | K51: =VLOOKUP(I51,gen_cost!$A$1:$AY$31,22) -> 0 | L51: =VLOOKUP(I51,gen_cost!$A$1:$AY$31,16) -> 0 | M51: =+L51 -> 0 | N51: =+M51 -> 0 | O51: =+N51 -> 0 | P51: =+O51 -> 0 | Q51: =+P51 -> 0 | R51: =VLOOKUP(I51,gen_cost!$A$1:$AY$31,14) -> 201.62 | S51: =+R51 -> 201.62 | T51: =+S51 -> 201.62 | U51: =+T51 -> 201.62 | V51: =+U51 -> 201.62 | W51: =+V51 -> 201.62 | X51: 20 | Y51: 10
...

Sheet lines
A1: ID | B1: province | C1: number_of_circuits | D1: network_node_code_starting | E1: network_node_code_ending | F1: voltage | G1: line_length_km | H1: reactance | I1: ttc_summer | J1: ttc_winter | K1: From | L1: To | M1: x_pu | N1: Susceptance | O1: Capacity
A2: 1 | B2: BC | C2: 1 | D2: BC_AAL_DSS | E2: BC_CBK_DSS | F2: 230 | G2: 161.71 | H2: 77.62 | I2: 397 | J2: 457 | K2: =VLOOKUP(D2,nodes!$A$1:$K$167,2) -> 1 | L2: =VLOOKUP(E2,nodes!$A$1:$K$167,2) -> 26 | M2: =H2/(F2^2/100) -> 0.14672968 | N2: =1/M2 -> 6.8152538 | O2: =J2/100 -> 4.57
A3: 2 | B3: BC | C3: 1 | D3: BC_ACK_DSS | E3: BC_SAM_DSS | F3: 230 | G3: 37.586 | H3: 18.04 | I3: 385 | J3: 461 | K3: =VLOOKUP(D3,nodes!$A$1:$K$167,2) -> 2 | L3: =VLOOKUP(E3,nodes!$A$1:$K$167,2) -> 123 | M3: =H3/(F3^2/100) -> 0.034102079 | N3: =1/M3 -> 29.323725 | O3: =J3/100 -> 4.61
A4: 3 | B4: BC | C4: 1 | D4: BC_ACK_DSS | E4: BC_VNT_TSS | F4: 230 | G4: 49.909 | H4: 23.96 | I4: 383 | J4: 461 | K4: =VLOOKUP(D4,nodes!$A$1:$K$167,2) -> 2 | L4: =VLOOKUP(E4,nodes!$A$1:$K$167,2) -> 156 | M4: =H4/(F4^2/100) -> 0.045293006 | N4: =1/M4 -> 22.078464 | O4: =J4/100 -> 4.61
A5: 4 | B5: BC | C5: 1 | D5: BC_ACK_DSS | E5: BC_VNT_TSS | F5: 230 | G5: 49.957 | H5: 23.98 | I5: 383 | J5: 460 | K5: =VLOOKUP(D5,nodes!$A$1:$K$167,2) -> 2 | L5: =VLOOKUP(E5,nodes!$A$1:$K$167,2) -> 156 | M5: =H5/(F5^2/100) -> 0.045330813 | N5: =1/M5 -> 22.06005 | O5: =J5/100 -> 4.6
A6: 5 | B6: BC | C6: 1 | D6: BC_ACK_DSS | E6: BC_NIC_TSS | F6: 500 | G6: 117.739 | H6: 46.51 | I6: 2633 | J6: 3036 | K6: =VLOOKUP(D6,nodes!$A$1:$K$167,2) -> 2 | L6: =VLOOKUP(E6,nodes!$A$1:$K$167,2) -> 101 | M6: =H6/(F6^2/100) -> 0.018604 | N6: =1/M6 -> 53.751881 | O6: =J6/100 -> 30.36
A7: 6 | B7: BC | C7: 1 | D7: BC_ACK_DSS | E7: BC_NIC_TSS | F7: 500 | G7: 117.776 | H7: 46.52 | I7: 2073 | J7: 2842 | K7: =VLOOKUP(D7,nodes!$A$1:$K$167,2) -> 2 | L7: =VLOOKUP(E7,nodes!$A$1:$K$167,2) -> 101 | M7: =H7/(F7^2/100) -> 0.018608 | N7: =1/M7 -> 53.740327 | O7: =J7/100 -> 28.42
A8: 7 | B8: BC | C8: 1 | D8: BC_ALH_GSS | E8: BC_BTS_TSS | F8: 230 | G8: 15 | H8: 7.2 | I8: 384 | J8: 459 | K8: =VLOOKUP(D8,nodes!$A$1:$K$167,2) -> 3 | L8: =VLOOKUP(E8,nodes!$A$1:$K$167,2) -> 23 | M8: =H8/(F8^2/100) -> 0.013610586 | N8: =1/M8 -> 73.472222 | O8: =J8/100 -> 4.59
A9: 8 | B9: BC | C9: 1 | D9: BC_ALZ_DSS | E9: BC_ROS_DSS | F9: 230 | G9: 19.132 | H9: 9.18 | I9: 610 | J9: 790 | K9: =VLOOKUP(D9,nodes!$A$1:$K$167,2) -> 4 | L9: =VLOOKUP(E9,nodes!$A$1:$K$167,2) -> 118 | M9: =H9/(F9^2/100) -> 0.017353497 | N9: =1/M9 -> 57.625272 | O9: =J9/100 -> 7.9
A10: 9 | B10: BC | C10: 1 | D10: BC_ARN_DSS | E10: BC_STV_DSS | F10: 230 | G10: 12.432 | H10: 5.97 | I10: 296 | J10: 390 | K10: =VLOOKUP(D10,nodes!$A$1:$K$167,2) -> 5 | L10: =VLOOKUP(E10,nodes!$A$1:$K$167,2) -> 138 | M10: =H10/(F10^2/100) -> 0.011285444 | N10: =1/M10 -> 88.609715 | O10: =J10/100 -> 3.9
A11: 10 | B11: BC | C11: 1 | D11: BC_ARN_DSS | E11: BC_EBT_TSS | F11: 230 | G11: 67.24 | H11: 32.28 | I11: 565 | J11: 669 | K11: =VLOOKUP(D11,nodes!$A$1:$K$167,2) -> 5 | L11: =VLOOKUP(E11,nodes!$A$1:$K$167,2) -> 39 | M11: =H11/(F11^2/100) -> 0.061020794 | N11: =1/M11 -> 16.387856 | O11: =J11/100 -> 6.69
A12: 11 | B12: BC | C12: 1 | D12: BC_ASL_JCT | E12: BC_ASL_GSS | F12: 230 | G12: 2.819 | H12: 1.35 | I12: 288 | J12: 389 | K12: =VLOOKUP(D12,nodes!$A$1:$K$167,2) -> 7 | L12: =VLOOKUP(E12,nodes!$A$1:$K$167,2) -> 6 | M12: =H12/(F12^2/100) -> 0.0025519849 | N12: =1/M12 -> 391.85185 | O12: =J12/100 -> 3.89
A13: 12 | B13: BC | C13: 1 | D13: BC_ASL_JCT | E13: BC_CMS_GSS | F13: 230 | G13: 19.8 | H13: 9.5 | I13: 288 | J13: 389 | K13: =VLOOKUP(D13,nodes!$A$1:$K$167,2) -> 7 | L13: =VLOOKUP(E13,nodes!$A$1:$K$167,2) -> 30 | M13: =H13/(F13^2/100) -> 0.017958412 | N13: =1/M13 -> 55.684211 | O13: =J13/100 -> 3.89
... A253: 254 | B253: BC | C253: 1 | D253: BC_WTS_TSS | E253: BC_BTS_TSS | F253: 230 | G253: 25 | H253: 12 | I253: 402 | J253: 435 | K253: =VLOOKUP(D253,nodes!$A$1:$K$167,2) -> 166 | L253: =VLOOKUP(E253,nodes!$A$1:$K$167,2) -> 23 | M253: =H253/(F253^2/100) -> 0.02268431 | N253: =1/M253 -> 44.083333 | O253: =J253/100 -> 4.35

Sheet gen_cost
A1: gen_type | B1: gen_type_source | C1: gen_type_copper | D1: gen_type_copper_source | E1: generation_type_description | F1: generic_generation_size_MW | G1: generic_generation_size_MW_source | H1: capital_cost_CAD_per_kW | I1: total_project_cost_CAD_per_kW | J1: economic_life | K1: economic_life_source | L1: service_life | M1: service_life_source | N1: annualized_capital_cost_CAD_per_kwyear | O1: fixed_om_costs | P1: variable_om_costs | Q1: construction_time | R1: development_time | S1: average_fuel_price_CAD_per_MMBtu | T1: average_fuel_price_CAD_per_MMBtu_source | U1: carbon_emissions | V1: heat_rate | W1: heat_rate_source | X1: efficiency | Y1: efficiency_source | Z1: min_plant_load | AA1: min_plant_load_source | AB1: min_capacity_factor | AC1: min_capacity_factor_source | AD1: max_capacity_factor | AE1: max_capacity_factor_source | AF1: time_to_full_capacity | AG1: time_to_full_capacity_source | AH1: min_up_time_hours | AI1: min_up_time_hours_source | AJ1: min_down_time_hours | AK1: min_down_time_hours_source | AL1: ramp_rate_percent_per_min | AM1: ramp_rate_percent_per_min_source | AN1: spinning_reserve_capability | AO1: spinning_reserve_capability_source | AP1: forced_outage_rate | AQ1: forced_outage_rate_source | AR1: planned_outage_rate | AS1: planned_outage_rate_source | AT1: startup_cost | AU1: startup_cost_source | AV1: shutdown_cost | AW1: shutdown_cost_source | AX1: notes | AY1: notes_source
A2: biogas | B2: N/A | C2: biomass | D2: N/A | E2: biogas | F2: 36 | G2: 51 | H2: 2442.96 | I2: 3016.27 | J2: 20 | K2: 20 | L2: 40 | M2: Estimated | N2: 307.21 | O2: 31512 | P2: 9.72 | Q2: 3 | S2: 3.03 | T2: 45 | U2: 0 | V2: 8.513 | W2: 51 | X2: 0.4008 | Y2: 51 | Z2: 0.4 | AA2: 201 | AB2: 0.55 | AC2: 48 | AD2: 0.7 | AE2: 48 | AF2: 60 | AG2: 46 | AH2: 8 | AI2: Estimated | AJ2: 8 | AK2: Estimated | AL2: 0.08 | AM2: 61 | AN2: 0 | AO2: 201 | AP2: 0.09 | AQ2: Estimated | AR2: 0.08 | AS2: Estimated | AT2: 8 | AU2: 243 | AV2: 0.08 | AW2: 243 | AX2: Municipal solid waste - landfill gas | AY2: 51
A3: biomass | B3: N/A | C3: biomass | D3: N/A | E3: biomass | F3: 50 | G3: 51 | H3: 6497.4 | I3: 8109.73 | J3: 30 | K3: 237 | L3: 45 | M3: 237 | N3: 720.37 | O3: 183950 | P3: 7.07 | Q3: 4 | R3: 6 | S3: 3.03 | T3: 45 | U3: 0 | V3: 13.5 | W3: 203 | X3: 0.2527 | Y3: 203 | Z3: 0.4 | AA3: 201 | AB3: 0.6 | AC3: 48 | AD3: 0.65 | AE3: 48 | AF3: 720 | AG3: 46 | AH3: 8 | AI3: Estimated | AJ3: 8 | AK3: Estimated | AL3: 0.08 | AM3: 61 | AN3: 0.06 | AO3: 201 | AP3: 0.09 | AQ3: 203 | AR3: 0.08 | AS3: 203 | AT3: 8 | AU3: 243 | AV3: 0.08 | AW3: 243 | AX3: NULL | AY3: N/A
A4: biomass_CG | B4: N/A | C4: biomass | D4: N/A | E4: biomass cogeneration | F4: 50 | G4: 51 | H4: 6497.4 | I4: 8109.73 | J4: 30 | K4: 237 | L4: 45 | M4: 237 | N4: 720.37 | O4: 183950 | P4: 7.07 | Q4: 4 | R4: 6 | S4: 3.03 | T4: 45 | U4: 0 | V4: 13.5 | W4: 203 | X4: 0.2527 | Y4: 203 | Z4: 0.4 | AA4: 201 | AB4: 0.6 | AC4: 48 | AD4: 0.65 | AE4: 48 | AF4: 720 | AG4: 46 | AH4: 8 | AI4: Estimated | AJ4: 8 | AK4: Estimated | AL4: 0.08 | AM4: 61 | AN4: 0.06 | AO4: 201 | AP4: 0.09 | AQ4: 203 | AR4: 0.08 | AS4: 203 | AT4: 8 | AU4: 243 | AV4: 0.08 | AW4: 243 | AX4: Assumed similar operations to biomass | AY4: N/A
A5: coal | B5: N/A | C5: coal | D5: N/A | E5: coal combined cycle | F5: 650 | G5: 51 | H5: 5859.1 | I5: 7326.05 | J5: 30 | K5: 237 | L5: 45 | M5: 237 | N5: 650.75 | O5: 59384 | P5: 6.58 | Q5: 4 | R5: 6 | S5: 2.5 | T5: 50 | U5: 0.808917 | V5: 8.47 | W5: 203 | X5: 0.4028 | Y5: 203 | Z5: 0.5 | AA5: 201 | AB5: 0.4 | AC5: 47 | AD5: 0.6 | AE5: 47 | AF5: 960 | AG5: 46 | AH5: 8 | AI5: 8 | AJ5: 8 | AK5: 8 | AL5: 0.06 | AM5: 61 | AN5: 0.5 | AO5: 201 | AP5: 0.06 | AQ5: 203 | AR5: 0.12 | AS5: 203 | AT5: 165 | AU5: 202 | AV5: 1.65 | AW5: 202 | AX5: Ultra-supercritical coal USC | AY5: 51
A6: coal_CCS | B6: N/A | C6: coalCCS | D6: N/A | E6: coal carbon capture and storage | F6: 650 | G6: 51 | H6: 9514.7 | I6: 11803.62 | J6: 30 | K6: 237 | L6: 45 | M6: 237 | N6: 1048.49 | O6: 87126 | P6: 16.06 | Q6: 4 | R6: 6 | S6: 2.5 | T6: 50 | U6: 0.103455 | V6: 10.83 | W6: 203 | X6: 0.3151 | Y6: 203 | Z6: 0.5 | AA6: 201 | AB6: 0.4 | AC6: 47 | AD6: 0.6 | AE6: 47 | AF6: 960 | AG6: 46 | AH6: 8 | AI6: 8 | AJ6: 8 | AK6: 8 | AL6: 0.06 | AM6: 61 | AN6: 0.5 | AO6: 201 | AP6: 0.08 | AQ6: 203 | AR6: 0.12 | AS6: 203 | AT6: 165 | AU6: 202 | AV6: 1.65 | AW6: 202 | AX6: Ultra-supercritical coal with 90% CCS | AY6: 51
A7: diesel_CT | B7: N/A | C7: diesel | D7: N/A | E7: diesel combustion turbine | F7: 21 | G7: 51 | H7: 2912 | I7: 3476.12 | J7: 30 | K7: 237 | L7: 45 | M7: 237 | N7: 308.77 | O7: 47853 | P7: 8.32 | Q7: 2 | R7: 3 | S7: 11.9 | T7: 50 | U7: 0.515469 | V7: 8.295 | W7: 51 | X7: 0.4113 | Y7: 51 | Z7: 0.5 | AA7: 201 | AB7: 0.01 | AC7: 47 | AD7: 0.02 | AE7: 47 | AF7: 10 | AG7: 46 | AH7: 1 | AI7: 8 | AJ7: 1 | AK7: 8 | AL7: 0.2 | AM7: 61 | AN7: 0.15 | AO7: 201 | AP7: 0.09 | AQ7: Estimated | AR7: 0.08 | AS7: Estimated | AT7: 200 | AU7: Estimated | AV7: 2 | AW7: Estimated | AX7: Internal combustion engine diesel | AY7: 51
A8: diesel_ST | B8: N/A | C8: diesel | D8: N/A | E8: diesel steam turbine | F8: 21 | G8: 51 | H8: 2912 | I8: 3476.12 | J8: 30 | K8: 237 | L8: 45 | M8: 237 | N8: 308.77 | O8: 47853 | P8: 8.32 | Q8: 2 | R8: 3 | S8: 11.9 | T8: 50 | U8: 0.515469 | V8: 8.295 | W8: 51 | X8: 0.4113 | Y8: 51 | Z8: 0.5 | AA8: 201 | AB8: 0.12 | AC8: 47 | AD8: 0.15 | AE8: 47 | AF8: 960 | AG8: 46 | AH8: 4 | AI8: 8 | AJ8: 2 | AK8: 8 | AL8: 0.07 | AM8: 61 | AN8: 0.15 | AO8: 201 | AP8: 0.09 | AQ8: Estimated | AR8: 0.08 | AS8: Estimated | AT8: 200 | AU8: Estimated | AV8: 2 | AW8: Estimated | AX8: Internal combustion engine diesel | AY8: 51
A9: gasoline_CT | B9: N/A | C9: diesel | D9: N/A | E9: gasoline combustion turbine | F9: 21 | G9: 51 | H9: 2912 | I9: 3476.12 | J9: 30 | K9: 237 | L9: 45 | M9: 237 | N9: 308.77 | O9: 47853 | P9: 8.32 | Q9: 2 | R9: 3 | S9: 11.9 | T9: 50 | U9: 0.515469 | V9: 8.295 | W9: 51 | X9: 0.4113 | Y9: 51 | Z9: 0.5 | AA9: 201 | AB9: 0.01 | AC9: 47 | AD9: 0.02 | AE9: 47 | AF9: 10 | AG9: 46 | AH9: 1 | AI9: 8 | AJ9: 1 | AK9: 8 | AL9: 0.2 | AM9: 61 | AN9: 0.15 | AO9: 201 | AP9: 0.09 | AQ9: Estimated | AR9: 0.08 | AS9: Estimated | AT9: 200 | AU9: Estimated | AV9: 2 | AW9: Estimated | AX9: Internal combustion engine diesel | AY9: 51
A10: geothermal | B10: N/A | C10: geothermal | D10: N/A | E10: geothermal binary cycle | F10: 50 | G10: 51 | H10: 4423.9 | I10: 5559.93 | J10: 40 | K10: 20 | L10: 40 | M10: 20 | N10: 466.26 | O10: 200174 | P10: 1.7 | Q10: 4 | R10: 6 | S10: 0 | T10: N/A | U10: 0 | V10: 8.946 | W10: 51 | X10: 0.3814 | Y10: 51 | Z10: 0.9 | AA10: 201 | AB10: 0.68 | AC10: 48 | AD10: 0.76 | AE10: 48 | AF10: 960 | AG10: 46 | AH10: 8 | AI10: Estimated | AJ10: 8 | AK10: Estimated | AL10: 0.05 | AM10: 61 | AN10: 0.15 | AO10: 201 | AP10: 0.05 | AQ10: Estimated | AR10: 0.1 | AS10: Estimated | AT10: 0 | AU10: Estimated | AV10: 0 | AW10: Estimated | AX10: NULL | AY10: N/A
A11: h2blue_CT | B11: N/A | C11: h2blue_CT | D11: N/A | E11: hydrogen combustion turbine | F11: 105 | G11: 9 | H11: 1856.4 | I11: 2239.19 | J11: 35 | K11: 205 | L11: 45 | M11: N/A | N11: 192.13 | O11: 60263 | P11: 4.87 | Q11: 2 | R11: 3 | S11: 17.1 | T11: 9 | U11: 0.0299 | V11: 9.9 | W11: 9 | X11: 0.3446 | Y11: 9 | Z11: 0 | AA11: 201 | AB11: 0.08 | AC11: 47 | AD11: 0.15 | AE11: 47 | AF11: 10 | AG11: 46 | AH11: 1 | AI11: Estimated | AJ11: 1 | AK11: Estimated | AL11: 0.2 | AM11: 61 | AN11: 0.83 | AO11: 201 | AP11: 0.05 | AQ11: 203 | AR11: 0.07 | AS11: 203 | AT11: 90 | AU11: 202 | AV11: 0.9 | AW11: 202 | AX11: Assumptions made similar to the natural gas CT based on discussions with AESO | AY11: N/A
A12: h2green_CT | B12: N/A | C12: h2green_CT | D12: N/A | E12: hydrogen combustion turbine | F12: 105 | G12: 9 | H12: 1856.4 | I12: 2239.19 | J12: 35 | K12: 205 | L12: 45 | M12: N/A | N12: 192.13 | O12: 60263 | P12: 4.87 | Q12: 2 | R12: 3 | S12: 61.83 | T12: 9 | U12: 0 | V12: 9.9 | W12: 9 | X12: 0.3446 | Y12: 9 | Z12: 0 | AA12: 201 | AB12: 0.08 | AC12: 47 | AD12: 0.15 | AE12: 47 | AF12: 10 | AG12: 46 | AH12: 1 | AI12: Estimated | AJ12: 1 | AK12: Estimated | AL12: 0.2 | AM12: 61 | AN12: 0.83 | AO12: 201 | AP12: 0.05 | AQ12: 203 | AR12: 0.07 | AS12: 203 | AT12: 90 | AU12: 202 | AV12: 0.9 | AW12: 202 | AX12: Assumptions made similar to the natural gas CT based on discussions with AESO | AY12: N/A
A13: hydro_daily | B13: N/A | C13: hydro_daily | D13: N/A | E13: hydroelectric daily storage | F13: 100 | G13: 51 | H13: 4447.3 | I13: 5588.78 | J13: 40 | K13: 20 | L13: 80 | M13: Estimated | N13: 468.68 | O13: 115196 | P13: 5 | Q13: 4 | R13: 6 | S13: 0 | T13: N/A | U13: 0 | W13: N/A | Y13: N/A | AA13: N/A | AC13: N/A | AE13: N/A | AF13: 10 | AG13: 46 | AH13: 1 | AI13: Estimated | AJ13: 1 | AK13: Estimated | AL13: 0.15 | AM13: 61 | AN13: 0.1 | AO13: 41 | AP13: 0.05 | AQ13: 41 | AR13: 0.1 | AS13: 41 | AT13: 0 | AU13: Estimated | AV13: 0 | AW13: Estimated | AX13: Conventional hydropower | AY13: 51
A14: hydro_monthly | B14: N/A | C14: hydro_monthly | D14: N/A | E14: hydroelectric monthly storage | F14: 700 | G14: N/A | H14: 9750 | I14: 13677.91 | J14: 70 | K14: 20 | L14: 100 | M14: Estimated | N14: 1099.26 | O14: 18305 | P14: 2 | Q14: 8 | R14: 12 | S14: 0 | T14: N/A | U14: 0 | W14: N/A | Y14: N/A | AA14: N/A | AC14: N/A | AE14: N/A | AF14: 10 | AG14: 46 | AH14: 1 | AI14: Estimated | AJ14: 1 | AK14: Estimated | AL14: 0.15 | AM14: 61 | AN14: 0.2 | AO14: 41 | AP14: 0.05 | AQ14: 41 | AR14: 0.1 | AS14: 41 | AT14: 0 | AU14: Estimated | AV14: 0 | AW14: Estimated | AX14: Capital cost based on $8.7B $2021 Keeyask Project | AY14: N/A
A15: hydro_run | B15: N/A | C15: hydro_run | D15: N/A | E15: hydroelectric non-storage | F15: 65 | G15: 20 | H15: 3692 | I15: 4656.52 | J15: 40 | K15: 20 | L15: 80 | M15: Estimated | N15: 390.5 | O15: 66563 | P15: 1 | Q15: 4 | R15: 6 | S15: 0 | T15: N/A | U15: 0 | W15: N/A | Y15: N/A | AA15: N/A | AC15: N/A | AE15: N/A | AF15: 10 | AG15: 46 | AH15: 1 | AI15: Estimated | AJ15: 1 | AK15: Estimated | AM15: N/A | AN15: 0 | AO15: 41 | AP15: 0.05 | AQ15: 41 | AR15: 0.1 | AS15: 41 | AT15: 0 | AU15: Estimated | AV15: 0 | AW15: Estimated | AX15: Capital cost based on BC Hydro RODAT data | AY15: N/A
A16: MSW | B16: N/A | C16: biomass | D16: N/A | E16: municipal solid waste | F16: 50 | G16: 51 | H16: 7059 | I16: 8798.5 | J16: 30 | K16: 237 | L16: 45 | M16: 237 | N16: 781.55 | O16: 183950 | P16: 7.07 | Q16: 4 | R16: 6 | S16: 3.03 | T16: 45 | U16: 0 | V16: 13.5 | W16: 203 | X16: 0.2527 | Y16: 203 | Z16: 0.4 | AA16: 201 | AB16: 0.6 | AC16: 48 | AD16: 0.65 | AE16: 48 | AF16: 720 | AG16: 46 | AH16: 8 | AI16: Estimated | AJ16: 8 | AK16: Estimated | AL16: 0.08 | AM16: 61 | AN16: 0.06 | AO16: 201 | AP16: 0.09 | AQ16: 203 | AR16: 0.08 | AS16: 203 | AT16: 8 | AU16: 243 | AV16: 0.08 | AW16: 243 | AX16: Assumed similar operations to biomass | AY16: N/A
A17: NG_CC | B17: N/A | C17: NG_CC | D17: N/A | E17: natural gas combined cycle | F17: 1083 | G17: 51 | H17: 1528.8 | I17: 1909.29 | J17: 30 | K17: 237 | L17: 45 | M17: 237 | N17: 169.6 | O17: 17849 | P17: 2.73 | Q17: 3 | R17: 5 | S17: 3.11 | T17: 50 | U17: 0.337527 | V17: 6.36 | W17: 203 | X17: 0.5365 | Y17: 203 | Z17: 0 | AA17: 201 | AB17: 0.45 | AC17: 47 | AD17: 0.58 | AE17: 47 | AF17: 720 | AG17: 46 | AH17: 4 | AI17: 104 | AJ17: 2 | AK17: 104 | AL17: 0.08 | AM17: 61 | AN17: 0.5 | AO17: 201 | AP17: 0.05 | AQ17: 203 | AR17: 0.1 | AS17: 203 | AT17: 103 | AU17: 202 | AV17: 1.03 | AW17: 202 | AX17: Natural gas combined cycle - multi shaft | AY17: 51
A18: NG_CCS | B18: N/A | C18: NG_CCS | D18: N/A | E18: natural gas carbon capture and storage | F18: 377 | G18: 51 | H18: 4082 | I18: 4985.71 | J18: 30 | K18: 237 | L18: 45 | M18: 237 | N18: 442.87 | O18: 40378 | P18: 8.54 | Q18: 3 | R18: 5 | S18: 3.11 | T18: 50 | U18: 0.037998 | V18: 7.16 | W18: 203 | X18: 0.4765 | Y18: 203 | Z18: 0 | AA18: 201 | AB18: 0.45 | AC18: 47 | AD18: 0.58 | AE18: 47 | AF18: 720 | AG18: 46 | AH18: 4 | AI18: 104 | AJ18: 2 | AK18: 104 | AL18: 0.08 | AM18: 61 | AN18: 0.5 | AO18: 201 | AP18: 0.05 | AQ18: 203 | AR18: 0.1 | AS18: 203 | AT18: 103 | AU18: 202 | AV18: 1.03 | AW18: 202 | AX18: Natural gas combined cycle with 90% CCS | AY18: 51
A19: NG_CG | B19: N/A | C19: NG_CG | D19: N/A | E19: natural gas cogeneration | F19: 1083 | G19: 51 | H19: 1528.8 | I19: 1909.29 | J19: 30 | K19: 237 | L19: 45 | M19: 237 | N19: 169.6 | O19: 17849 | P19: 2.73 | Q19: 3 | R19: 5 | S19: 3.11 | T19: 50 | U19: 0.3375 | V19: 7.16 | W19: 203 | X19: 0.4765 | Y19: 203 | Z19: 0 | AA19: 201 | AB19: 0.45 | AC19: 47 | AD19: 0.58 | AE19: 47 | AF19: 720 | AG19: 46 | AH19: 4 | AI19: 104 | AJ19: 2 | AK19: 104 | AL19: 0.08 | AM19: 61 | AN19: 0.5 | AO19: 201 | AP19: 0.05 | AQ19: 203 | AR19: 0.1 | AS19: 203 | AT19: 103 | AU19: 202 | AV19: 1.03 | AW19: 202 | AX19: Assumed similar to costs and operations to natural gas combined cycle | AY19: N/A
A20: NG_SC | B20: N/A | C20: NG_SC | D20: N/A | E20: natural gas simple cycle | F20: 105 | G20: 51 | H20: 1856.4 | I20: 2239.19 | J20: 30 | K20: 237 | L20: 45 | M20: 237 | N20: 198.9 | O20: 23855 | P20: 6.88 | Q20: 2 | R20: 3 | S20: 3.11 | T20: 50 | U20: 0.515843 | V20: 9.72 | W20: 203 | X20: 0.351 | Y20: 203 | Z20: 0 | AA20: 201 | AB20: 0.08 | AC20: 47 | AD20: 0.15 | AE20: 47 | AF20: 10 | AG20: 46 | AH20: 1 | AI20: 104 | AJ20: 1 | AK20: 104 | AL20: 0.2 | AM20: 61 | AN20: 0.83 | AO20: 201 | AP20: 0.05 | AQ20: 203 | AR20: 0.07 | AS20: 203 | AT20: 90 | AU20: 202 | AV20: 0.9 | AW20: 202 | AX20: Combustion turbine - aeroderivative | AY20: 51
A21: nuclear | B21: N/A | C21: nuclear | D21: N/A | E21: nuclear light water reactor | F21: 2156 | G21: 51 | H21: 10110.1 | I21: 13320.33 | J21: 30 | K21: 237 | L21: 60 | M21: 237 | N21: 1183.21 | O21: 177983 | P21: 3.47 | Q21: 6 | R21: 10 | S21: 0.86 | T21: 49 | U21: 0 | V21: 10.44 | W21: 203 | X21: 0.3268 | Y21: 203 | Z21: 1 | AA21: 201 | AB21: 0.86 | AC21: 48 | AD21: 0.94 | AE21: 48 | AF21: 960 | AG21: 46 | AH21: 24 | AI21: Estimated | AJ21: 24 | AK21: Estimated | AL21: 0.02 | AM21: 61 | AN21: 0.1 | AO21: 201 | AP21: 0.03 | AQ21: 203 | AR21: 0.06 | AS21: 203 | AT21: 0 | AU21: 202 | AV21: 0 | AW21: 202 | AX21: NULL | AY21: N/A
A22: nuclear_SMR | B22: N/A | C22: nuclear_SMR | D22: N/A | E22: nuclear small modular reactor | F22: 600 | G22: 51 | H22: 10853.7 | I22: 14285.21 | J22: 30 | K22: 237 | L22: 60 | M22: 237 | N22: 1268.92 | O22: 138996 | P22: 4.39 | Q22: 6 | R22: 10 | S22: 0.86 | T22: 49 | U22: 0 | V22: 10.44 | W22: 203 | X22: 0.3268 | Y22: 203 | Z22: 1 | AA22: 201 | AB22: 0.86 | AC22: 48 | AD22: 0.94 | AE22: 48 | AF22: 960 | AG22: 46 | AH22: 24 | AI22: Estimated | AJ22: 24 | AK22: Estimated | AL22: 0.02 | AM22: 61 | AN22: 0.1 | AO22: 201 | AP22: 0.03 | AQ22: 203 | AR22: 0.06 | AS22: 203 | AT22: 0 | AU22: 202 | AV22: 0 | AW22: 202 | AX22: Assumed similar to operations to conventional nuclear | AY22: N/A
A23: oil_CT | B23: N/A | C23: diesel | D23: N/A | E23: oil combustion turbine | F23: 21 | G23: 51 | H23: 2912 | I23: 3476.12 | J23: 30 | K23: 237 | L23: 45 | M23: 237 | N23: 308.77 | O23: 51441 | P23: 8.32 | Q23: 2 | R23: 3 | S23: 11.9 | T23: 50 | U23: 0.515469 | V23: 8.295 | W23: 51 | X23: 0.4113 | Y23: 51 | Z23: 0.5 | AA23: 201 | AB23: 0.01 | AC23: 47 | AD23: 0.02 | AE23: 47 | AF23: 10 | AG23: 46 | AH23: 1 | AI23: 8 | AJ23: 1 | AK23: 8 | AL23: 0.2 | AM23: 61 | AN23: 0.15 | AO23: 201 | AP23: 0.09 | AQ23: Estimated | AR23: 0.08 | AS23: Estimated | AT23: 200 | AU23: Estimated | AV23: 2 | AW23: Estimated | AX23: Internal combustion engine diesel | AY23: 51
A24: oil_ST | B24: N/A | C24: diesel | D24: N/A | E24: oil steam turbine | F24: 21 | G24: 51 | H24: 2912 | I24: 3476.12 | J24: 30 | K24: 237 | L24: 45 | M24: 237 | N24: 308.77 | O24: 51441 | P24: 8.32 | Q24: 2 | R24: 3 | S24: 11.9 | T24: 50 | U24: 0.515469 | V24: 8.295 | W24: 51 | X24: 0.4113 | Y24: 51 | Z24: 0.5 | AA24: 201 | AB24: 0.12 | AC24: 47 | AD24: 0.15 | AE24: 47 | AF24: 960 | AG24: 46 | AH24: 4 | AI24: 8 | AJ24: 2 | AK24: 8 | AL24: 0.07 | AM24: 61 | AN24: 0.15 | AO24: 201 | AP24: 0.09 | AQ24: Estimated | AR24: 0.08 | AS24: Estimated | AT24: 200 | AU24: Estimated | AV24: 2 | AW24: Estimated | AX24: Internal combustion engine diesel | AY24: 51
A25: solar_PV | B25: N/A | C25: solar | D25: N/A | E25: solar photovoltaic | F25: 150 | G25: 51 | H25: 1882.4 | I25: 2269.77 | J25: 30 | K25: 203 | L25: 30 | M25: 203 | N25: 201.62 | O25: 22308 | P25: 0 | Q25: 2 | R25: 3 | S25: 0 | T25: N/A | U25: 0 | W25: N/A | Y25: N/A | Z25: 0 | AA25: 201 | AC25: N/A | AE25: N/A | AG25: N/A | AI25: N/A | AK25: N/A | AM25: N/A | AN25: 0 | AO25: 201 | AP25: 0 | AQ25: Estimated | AR25: 0 | AS25: Estimated | AT25: 0 | AU25: Estimated | AV25: 0 | AW25: Estimated | AX25: Costs and capacities in terms of net AC power available to the grid for the installed capacity | AY25: 51
A26: solar_recon | B26: N/A | C26: solar_recon | D26: N/A | E26: recontracted solar photovoltaic | F26: 150 | G26: 51 | H26: 1505.92 | I26: 1772.95 | J26: 30 | K26: 203 | L26: 30 | M26: 203 | N26: 157.49 | O26: 22308 | P26: 0 | Q26: 1 | R26: 2 | S26: 0 | T26: N/A | U26: 0 | W26: N/A | Y26: N/A | Z26: 0 | AA26: 201 | AC26: N/A | AE26: N/A | AG26: N/A | AI26: N/A | AK26: N/A | AM26: N/A | AN26: 0 | AO26: 201 | AP26: 0 | AQ26: Estimated | AR26: 0 | AS26: Estimated | AT26: 0 | AU26: Estimated | AV26: 0 | AW26: Estimated | AX26: 80% capital cost per MW of greenfield solar PV based on NREL data | AY26: N/A
A27: storage_lithium | B27: N/A | C27: storage_LI | D27: N/A | E27: lithium ion battery storage | F27: 50 | G27: 51 | H27: 1651 | I27: 1939.13 | J27: 15 | K27: 203 | L27: 15 | M27: 203 | N27: 226.55 | O27: 59488 | P27: 0 | Q27: 1 | R27: 1 | S27: 0 | T27: N/A | U27: 0 | W27: N/A | Y27: N/A | Z27: 0 | AA27: 201 | AB27: 0 | AC27: 205 | AD27: 0.1667 | AE27: 205 | AF27: 10 | AG27: 46 | AH27: 1 | AI27: Estimated | AJ27: 1 | AK27: Estimated | AL27: 1 | AM27: 61 | AN27: 0.5 | AO27: Estimated | AP27: 0.05 | AQ27: Estimated | AR27: 0.1 | AS27: Estimated | AT27: 0 | AU27: Estimated | AV27: 0 | AW27: Estimated | AX27: Four-hour battery storage | AY27: 51
A28: storage_pump | B28: N/A | C28: storage_PH | D28: N/A | E28: hydroelectric pumped storage | F28: 1000 | G28: 28 | H28: 4290 | I28: 5734.68 | J28: 70 | K28: 20 | L28: 100 | M28: Estimated | N28: 460.88 | O28: 15844 | P28: 1 | Q28: 6 | R28: 8 | S28: 0 | T28: N/A | U28: 0 | W28: N/A | Y28: N/A | AA28: N/A | AB28: 0 | AC28: Estimated | AD28: 0.3 | AE28: Estimated | AF28: 10 | AG28: 46 | AH28: 1 | AI28: Estimated | AJ28: 1 | AK28: Estimated | AL28: 0.15 | AM28: 61 | AN28: 0.5 | AO28: Estimated | AP28: 0.05 | AQ28: 41 | AR28: 0.1 | AS28: 41 | AT28: 0 | AU28: Estimated | AV28: 0 | AW28: Estimated | AX28: Capital cost based on $4.3B Meaford Pumped Storage Project | AY28: N/A
A29: wind_offshore | B29: N/A | C29: wind_ofs | D29: N/A | E29: offshore wind | F29: 400 | G29: 51 | H29: 8673.6 | I29: 10775.41 | J29: 30 | K29: 203 | L29: 30 | M29: 203 | N29: 957.15 | O29: 160953 | P29: 0 | Q29: 4 | R29: 6 | S29: 0 | T29: N/A | U29: 0 | W29: N/A | Y29: N/A | Z29: 0 | AA29: 201 | AC29: N/A | AE29: N/A | AG29: N/A | AI29: N/A | AK29: N/A | AM29: N/A | AN29: 0 | AO29: 201 | AP29: 0.01 | AQ29: Estimated | AR29: 0.01 | AS29: Estimated | AT29: 0 | AU29: Estimated | AV29: 0 | AW29: Estimated | AX29: TRG - 5 Mid 2021 | AY29: N/A
A30: wind_onshore | B30: N/A | C30: wind_ons | D30: N/A | E30: onshore wind | F30: 200 | G30: 51 | H30: 2727.4 | I30: 3359.17 | J30: 30 | K30: 203 | L30: 30 | M30: 203 | N30: 298.39 | O30: 38532 | P30: 0 | Q30: 3 | R30: 5 | S30: 0 | T30: N/A | U30: 0 | W30: N/A | Y30: N/A | Z30: 0 | AA30: 201 | AC30: N/A | AE30: N/A | AG30: N/A | AI30: N/A | AK30: N/A | AM30: N/A | AN30: 0 | AO30: 201 | AP30: 0.01 | AQ30: Estimated | AR30: 0.01 | AS30: Estimated | AT30: 0 | AU30: Estimated | AV30: 0 | AW30: Estimated | AX30: TRG - 5 Mid 2021 | AY30: N/A
A31: wind_recon | B31: N/A | C31: wind_recon | D31: N/A | E31: recontracted onshore wind | F31: 200 | G31: 51 | H31: 2181.92 | I31: 2621.61 | J31: 30 | K31: 203 | L31: 30 | M31: 203 | N31: 232.87 | O31: 38532 | P31: 0 | Q31: 2 | R31: 4 | S31: 0 | T31: N/A | U31: 0 | W31: N/A | Y31: N/A | Z31: 0 | AA31: 201 | AC31: N/A | AE31: N/A | AG31: N/A | AI31: N/A | AK31: N/A | AM31: N/A | AN31: 0 | AO31: 201 | AP31: 0.01 | AQ31: Estimated | AR31: 0.01 | AS31: Estimated | AT31: 0 | AU31: Estimated | AV31: 0 | AW31: Estimated | AX31: 80% capital cost per MW of greenfield onshore wind based on NREL data | AY31: N/A

Sheet economic
A1: t | B1: carbon_tax | C1: a | D1: rho_o1 | E1: rho_o2 | F1: rho_o3 | G1: rho_o4 | H1: rho_o5 | I1: rho_o6 | J1: rho_o7 | K1: rho_o8 | L1: rho_o9 | M1: rho_o10 | N1: rho_o11 | O1: rho_o12 | P1: rho_o13 | Q1: rho_o14 | R1: rho_o15 | S1: rho_o16 | T1: rho_o17 | U1: rho_o18 | V1: rho_o19 | W1: rho_o20 | X1: rho_o21 | Y1: rho_o22 | Z1: rho_o23 | AA1: rho_o24 | AB1: rho_o25 | AC1: rho_o26 | AD1: rho_o27 | AE1: rho_o28 | AF1: rho_o29 | AG1: rho_o30 | AH1: rho_o31 | AI1: rho_o32 | AJ1: rho_o33 | AK1: rho_o34 | AL1: rho_o35 | AM1: rho_o36 | AN1: rho_o37 | AO1: rho_o38 | AP1: rho_o39 | AQ1: rho_o40 | AR1: rho_o41 | AS1: rho_o42 | AT1: rho_o43 | AU1: rho_o44 | AV1: rho_o45 | AW1: rho_o46 | AX1: rho_o47 | AY1: rho_o48
A2: 1 | B2: 70.49 | C2: 0.2 | D2: =factors!C26 -> 59 | E2: =factors!D26 -> 87 | F2: =factors!E26 -> 111 | G2: =factors!F26 -> 158 | H2: =factors!G26 -> 4 | I2: =factors!H26 -> 324 | J2: =factors!I26 -> 328 | K2: =factors!J26 -> 332 | ... AY2: =factors!AX26 -> 221
A3: 2 | B3: 126.14 | C3: 0.18 | D3: =factors!C27 -> 251 | E3: =factors!D27 -> 328 | F3: =factors!E27 -> 80 | G3: =factors!F27 -> 101 | H3: =factors!G27 -> 84 | I3: =factors!H27 -> 91 | J3: =factors!I27 -> 154 | K3: =factors!J27 -> 136 | ... AY3: =factors!AX27 -> 339
A4: 3 | B4: 126.14 | C4: 0.17 | D4: =factors!C28 -> 366 | E4: =factors!D28 -> 290 | F4: =factors!E28 -> 362 | G4: =factors!F28 -> 137 | H4: =factors!G28 -> 125 | I4: =factors!H28 -> 48 | J4: =factors!I28 -> 258 | K4: =factors!J28 -> 76 | ... AY4: =factors!AX28 -> 7
A5: 4 | B5: 126.14 | C5: 0.16 | D5: =factors!C29 -> 82 | E5: =factors!D29 -> 225 | F5: =factors!E29 -> 108 | G5: =factors!F29 -> 216 | H5: =factors!G29 -> 163 | I5: =factors!H29 -> 225 | J5: =factors!I29 -> 320 | K5: =factors!J29 -> 265 | ... AY5: =factors!AX29 -> 289
A6: 5 | B6: 126.14 | C6: 0.15 | D6: =factors!C30 -> 18 | E6: =factors!D30 -> 290 | F6: =factors!E30 -> 147 | G6: =factors!F30 -> 66 | H6: =factors!G30 -> 346 | I6: =factors!H30 -> 221 | J6: =factors!I30 -> 48 | K6: =factors!J30 -> 143 | ... AY6: =factors!AX30 -> 149
A7: 6 | B7: 126.14 | C7: 0.14 | D7: =factors!C31 -> 249 | E7: =factors!D31 -> 25 | F7: =factors!E31 -> 287 | G7: =factors!F31 -> 38 | H7: =factors!G31 -> 28 | I7: =factors!H31 -> 88 | J7: =factors!I31 -> 148 | K7: =factors!J31 -> 54 | ... AY7: =factors!AX31 -> 265

Sheet demand
